2022-07-24 01:03:13,134 (__init__.py:615 MainThread) ERROR - TeleBot: "Infinity polling exception: HTTPSConnectionPool(host='api.remonline.app', port=443): Max retries exceeded with url: /token/new?api_key=c0c5fe906bb14f828316f6e255d17859 (Caused by NewConnectionError('<urllib3.connection.HTTPSConnection object at 0x7f5618794490>: Failed to establish a new connection: [Errno 101] Сеть недоступна'))"
2022-07-24 01:03:13,165 (__init__.py:617 MainThread) ERROR - TeleBot: "Exception traceback:
Traceback (most recent call last):
  File "/usr/local/lib/python3.10/site-packages/urllib3/connection.py", line 174, in _new_conn
    conn = connection.create_connection(
  File "/usr/local/lib/python3.10/site-packages/urllib3/util/connection.py", line 95, in create_connection
    raise err
  File "/usr/local/lib/python3.10/site-packages/urllib3/util/connection.py", line 85, in create_connection
    sock.connect(sa)
OSError: [Errno 101] Сеть недоступна

During handling of the above exception, another exception occurred:

Traceback (most recent call last):
  File "/usr/local/lib/python3.10/site-packages/urllib3/connectionpool.py", line 703, in urlopen
    httplib_response = self._make_request(
  File "/usr/local/lib/python3.10/site-packages/urllib3/connectionpool.py", line 386, in _make_request
    self._validate_conn(conn)
  File "/usr/local/lib/python3.10/site-packages/urllib3/connectionpool.py", line 1040, in _validate_conn
    conn.connect()
  File "/usr/local/lib/python3.10/site-packages/urllib3/connection.py", line 358, in connect
    conn = self._new_conn()
  File "/usr/local/lib/python3.10/site-packages/urllib3/connection.py", line 186, in _new_conn
    raise NewConnectionError(
urllib3.exceptions.NewConnectionError: <urllib3.connection.HTTPSConnection object at 0x7f5618794490>: Failed to establish a new connection: [Errno 101] Сеть недоступна

During handling of the above exception, another exception occurred:

Traceback (most recent call last):
  File "/usr/local/lib/python3.10/site-packages/requests/adapters.py", line 440, in send
    resp = conn.urlopen(
  File "/usr/local/lib/python3.10/site-packages/urllib3/connectionpool.py", line 785, in urlopen
    retries = retries.increment(
  File "/usr/local/lib/python3.10/site-packages/urllib3/util/retry.py", line 592, in increment
    raise MaxRetryError(_pool, url, error or ResponseError(cause))
urllib3.exceptions.MaxRetryError: HTTPSConnectionPool(host='api.remonline.app', port=443): Max retries exceeded with url: /token/new?api_key=c0c5fe906bb14f828316f6e255d17859 (Caused by NewConnectionError('<urllib3.connection.HTTPSConnection object at 0x7f5618794490>: Failed to establish a new connection: [Errno 101] Сеть недоступна'))

During handling of the above exception, another exception occurred:

Traceback (most recent call last):
  File "/usr/local/lib/python3.10/site-packages/telebot/__init__.py", line 611, in infinity_polling
    self.polling(none_stop=True, timeout=timeout, long_polling_timeout=long_polling_timeout,
  File "/usr/local/lib/python3.10/site-packages/telebot/__init__.py", line 658, in polling
    self.__threaded_polling(non_stop, interval, timeout, long_polling_timeout, allowed_updates)
  File "/usr/local/lib/python3.10/site-packages/telebot/__init__.py", line 720, in __threaded_polling
    raise e
  File "/usr/local/lib/python3.10/site-packages/telebot/__init__.py", line 680, in __threaded_polling
    self.worker_pool.raise_exceptions()
  File "/usr/local/lib/python3.10/site-packages/telebot/util.py", line 135, in raise_exceptions
    raise self.exception_info
  File "/usr/local/lib/python3.10/site-packages/telebot/util.py", line 87, in run
    task(*args, **kwargs)
  File "/home/RemBot/client/bot.py", line 55, in message_handler
    handler(bot, message)
  File "/home/RemBot/client/commands.py", line 37, in menu_command_handler
    client = ro_api.get_client_by_phone_number(user.phone_number)
  File "/home/RemBot/server/backend/ro_api.py", line 69, in get_client_by_phone_number
    clients = get_clients(**{'phones[]': phone_number})
  File "/home/RemBot/server/backend/ro_api.py", line 64, in get_clients
    data = get_json(prefix, params).data
  File "/home/RemBot/server/backend/ro_api.py", line 49, in get_json
    params.update({'token': get_new_token()})
  File "/home/RemBot/server/backend/ro_api.py", line 44, in get_new_token
    return requests.get(url, params).json()['token']
  File "/usr/local/lib/python3.10/site-packages/requests/api.py", line 75, in get
    return request('get', url, params=params, **kwargs)
  File "/usr/local/lib/python3.10/site-packages/requests/api.py", line 61, in request
    return session.request(method=method, url=url, **kwargs)
  File "/usr/local/lib/python3.10/site-packages/requests/sessions.py", line 529, in request
    resp = self.send(prep, **send_kwargs)
  File "/usr/local/lib/python3.10/site-packages/requests/sessions.py", line 645, in send
    r = adapter.send(request, **kwargs)
  File "/usr/local/lib/python3.10/site-packages/requests/adapters.py", line 519, in send
    raise ConnectionError(e, request=request)
requests.exceptions.ConnectionError: HTTPSConnectionPool(host='api.remonline.app', port=443): Max retries exceeded with url: /token/new?api_key=c0c5fe906bb14f828316f6e255d17859 (Caused by NewConnectionError('<urllib3.connection.HTTPSConnection object at 0x7f5618794490>: Failed to establish a new connection: [Errno 101] Сеть недоступна'))
"
2022-07-26 10:45:03,874 (__init__.py:615 MainThread) ERROR - TeleBot: "Infinity polling exception: 'bonus'"
2022-07-26 10:45:03,876 (__init__.py:617 MainThread) ERROR - TeleBot: "Exception traceback:
Traceback (most recent call last):
  File "/usr/local/lib/python3.10/site-packages/telebot/__init__.py", line 611, in infinity_polling
    self.polling(none_stop=True, timeout=timeout, long_polling_timeout=long_polling_timeout,
  File "/usr/local/lib/python3.10/site-packages/telebot/__init__.py", line 658, in polling
    self.__threaded_polling(non_stop, interval, timeout, long_polling_timeout, allowed_updates)
  File "/usr/local/lib/python3.10/site-packages/telebot/__init__.py", line 720, in __threaded_polling
    raise e
  File "/usr/local/lib/python3.10/site-packages/telebot/__init__.py", line 680, in __threaded_polling
    self.worker_pool.raise_exceptions()
  File "/usr/local/lib/python3.10/site-packages/telebot/util.py", line 135, in raise_exceptions
    raise self.exception_info
  File "/usr/local/lib/python3.10/site-packages/telebot/util.py", line 87, in run
    task(*args, **kwargs)
  File "/home/RemBot/client/bot.py", line 105, in callback_query_handler
    handler(bot, call)
  File "/home/RemBot/client/handlers.py", line 176, in discounts_callback_query_handler
    text = Messages.DISCOUNTS.format(name=user.name)
KeyError: 'bonus'
"
2022-07-26 10:45:14,658 (__init__.py:615 MainThread) ERROR - TeleBot: "Infinity polling exception: 'bonus'"
2022-07-26 10:45:14,658 (__init__.py:617 MainThread) ERROR - TeleBot: "Exception traceback:
Traceback (most recent call last):
  File "/usr/local/lib/python3.10/site-packages/telebot/__init__.py", line 611, in infinity_polling
    self.polling(none_stop=True, timeout=timeout, long_polling_timeout=long_polling_timeout,
  File "/usr/local/lib/python3.10/site-packages/telebot/__init__.py", line 658, in polling
    self.__threaded_polling(non_stop, interval, timeout, long_polling_timeout, allowed_updates)
  File "/usr/local/lib/python3.10/site-packages/telebot/__init__.py", line 720, in __threaded_polling
    raise e
  File "/usr/local/lib/python3.10/site-packages/telebot/__init__.py", line 680, in __threaded_polling
    self.worker_pool.raise_exceptions()
  File "/usr/local/lib/python3.10/site-packages/telebot/util.py", line 135, in raise_exceptions
    raise self.exception_info
  File "/usr/local/lib/python3.10/site-packages/telebot/util.py", line 87, in run
    task(*args, **kwargs)
  File "/home/RemBot/client/bot.py", line 105, in callback_query_handler
    handler(bot, call)
  File "/home/RemBot/client/handlers.py", line 176, in discounts_callback_query_handler
    text = Messages.DISCOUNTS.format(name=user.name)
KeyError: 'bonus'
"
2022-07-26 10:45:24,536 (__init__.py:615 MainThread) ERROR - TeleBot: "Infinity polling exception: 'bonus'"
2022-07-26 10:45:24,536 (__init__.py:617 MainThread) ERROR - TeleBot: "Exception traceback:
Traceback (most recent call last):
  File "/usr/local/lib/python3.10/site-packages/telebot/__init__.py", line 611, in infinity_polling
    self.polling(none_stop=True, timeout=timeout, long_polling_timeout=long_polling_timeout,
  File "/usr/local/lib/python3.10/site-packages/telebot/__init__.py", line 658, in polling
    self.__threaded_polling(non_stop, interval, timeout, long_polling_timeout, allowed_updates)
  File "/usr/local/lib/python3.10/site-packages/telebot/__init__.py", line 720, in __threaded_polling
    raise e
  File "/usr/local/lib/python3.10/site-packages/telebot/__init__.py", line 680, in __threaded_polling
    self.worker_pool.raise_exceptions()
  File "/usr/local/lib/python3.10/site-packages/telebot/util.py", line 135, in raise_exceptions
    raise self.exception_info
  File "/usr/local/lib/python3.10/site-packages/telebot/util.py", line 87, in run
    task(*args, **kwargs)
  File "/home/RemBot/client/bot.py", line 105, in callback_query_handler
    handler(bot, call)
  File "/home/RemBot/client/handlers.py", line 176, in discounts_callback_query_handler
    text = Messages.DISCOUNTS.format(name=user.name)
KeyError: 'bonus'
"
2022-07-26 10:45:39,777 (__init__.py:615 MainThread) ERROR - TeleBot: "Infinity polling exception: 'bonus'"
2022-07-26 10:45:39,777 (__init__.py:617 MainThread) ERROR - TeleBot: "Exception traceback:
Traceback (most recent call last):
  File "/usr/local/lib/python3.10/site-packages/telebot/__init__.py", line 611, in infinity_polling
    self.polling(none_stop=True, timeout=timeout, long_polling_timeout=long_polling_timeout,
  File "/usr/local/lib/python3.10/site-packages/telebot/__init__.py", line 658, in polling
    self.__threaded_polling(non_stop, interval, timeout, long_polling_timeout, allowed_updates)
  File "/usr/local/lib/python3.10/site-packages/telebot/__init__.py", line 720, in __threaded_polling
    raise e
  File "/usr/local/lib/python3.10/site-packages/telebot/__init__.py", line 680, in __threaded_polling
    self.worker_pool.raise_exceptions()
  File "/usr/local/lib/python3.10/site-packages/telebot/util.py", line 135, in raise_exceptions
    raise self.exception_info
  File "/usr/local/lib/python3.10/site-packages/telebot/util.py", line 87, in run
    task(*args, **kwargs)
  File "/home/RemBot/client/bot.py", line 105, in callback_query_handler
    handler(bot, call)
  File "/home/RemBot/client/handlers.py", line 176, in discounts_callback_query_handler
    text = Messages.DISCOUNTS.format(name=user.name)
KeyError: 'bonus'
"
2022-07-26 10:45:52,930 (__init__.py:615 MainThread) ERROR - TeleBot: "Infinity polling exception: 'bonus'"
2022-07-26 10:45:52,930 (__init__.py:617 MainThread) ERROR - TeleBot: "Exception traceback:
Traceback (most recent call last):
  File "/usr/local/lib/python3.10/site-packages/telebot/__init__.py", line 611, in infinity_polling
    self.polling(none_stop=True, timeout=timeout, long_polling_timeout=long_polling_timeout,
  File "/usr/local/lib/python3.10/site-packages/telebot/__init__.py", line 658, in polling
    self.__threaded_polling(non_stop, interval, timeout, long_polling_timeout, allowed_updates)
  File "/usr/local/lib/python3.10/site-packages/telebot/__init__.py", line 720, in __threaded_polling
    raise e
  File "/usr/local/lib/python3.10/site-packages/telebot/__init__.py", line 680, in __threaded_polling
    self.worker_pool.raise_exceptions()
  File "/usr/local/lib/python3.10/site-packages/telebot/util.py", line 135, in raise_exceptions
    raise self.exception_info
  File "/usr/local/lib/python3.10/site-packages/telebot/util.py", line 87, in run
    task(*args, **kwargs)
  File "/home/RemBot/client/bot.py", line 105, in callback_query_handler
    handler(bot, call)
  File "/home/RemBot/client/handlers.py", line 176, in discounts_callback_query_handler
    text = Messages.DISCOUNTS.format(name=user.name)
KeyError: 'bonus'
"
2022-07-26 10:45:55,935 (__init__.py:615 MainThread) ERROR - TeleBot: "Infinity polling exception: 'bonus'"
2022-07-26 10:45:55,935 (__init__.py:617 MainThread) ERROR - TeleBot: "Exception traceback:
Traceback (most recent call last):
  File "/usr/local/lib/python3.10/site-packages/telebot/__init__.py", line 611, in infinity_polling
    self.polling(none_stop=True, timeout=timeout, long_polling_timeout=long_polling_timeout,
  File "/usr/local/lib/python3.10/site-packages/telebot/__init__.py", line 658, in polling
    self.__threaded_polling(non_stop, interval, timeout, long_polling_timeout, allowed_updates)
  File "/usr/local/lib/python3.10/site-packages/telebot/__init__.py", line 720, in __threaded_polling
    raise e
  File "/usr/local/lib/python3.10/site-packages/telebot/__init__.py", line 680, in __threaded_polling
    self.worker_pool.raise_exceptions()
  File "/usr/local/lib/python3.10/site-packages/telebot/util.py", line 135, in raise_exceptions
    raise self.exception_info
  File "/usr/local/lib/python3.10/site-packages/telebot/util.py", line 87, in run
    task(*args, **kwargs)
  File "/home/RemBot/client/bot.py", line 105, in callback_query_handler
    handler(bot, call)
  File "/home/RemBot/client/handlers.py", line 176, in discounts_callback_query_handler
    text = Messages.DISCOUNTS.format(name=user.name)
KeyError: 'bonus'
"
2022-07-26 10:45:58,939 (__init__.py:615 MainThread) ERROR - TeleBot: "Infinity polling exception: 'bonus'"
2022-07-26 10:45:58,940 (__init__.py:617 MainThread) ERROR - TeleBot: "Exception traceback:
Traceback (most recent call last):
  File "/usr/local/lib/python3.10/site-packages/telebot/__init__.py", line 611, in infinity_polling
    self.polling(none_stop=True, timeout=timeout, long_polling_timeout=long_polling_timeout,
  File "/usr/local/lib/python3.10/site-packages/telebot/__init__.py", line 658, in polling
    self.__threaded_polling(non_stop, interval, timeout, long_polling_timeout, allowed_updates)
  File "/usr/local/lib/python3.10/site-packages/telebot/__init__.py", line 720, in __threaded_polling
    raise e
  File "/usr/local/lib/python3.10/site-packages/telebot/__init__.py", line 680, in __threaded_polling
    self.worker_pool.raise_exceptions()
  File "/usr/local/lib/python3.10/site-packages/telebot/util.py", line 135, in raise_exceptions
    raise self.exception_info
  File "/usr/local/lib/python3.10/site-packages/telebot/util.py", line 87, in run
    task(*args, **kwargs)
  File "/home/RemBot/client/bot.py", line 105, in callback_query_handler
    handler(bot, call)
  File "/home/RemBot/client/handlers.py", line 176, in discounts_callback_query_handler
    text = Messages.DISCOUNTS.format(name=user.name)
KeyError: 'bonus'
"
2022-07-26 10:46:01,942 (__init__.py:615 MainThread) ERROR - TeleBot: "Infinity polling exception: 'bonus'"
2022-07-26 10:46:01,944 (__init__.py:617 MainThread) ERROR - TeleBot: "Exception traceback:
Traceback (most recent call last):
  File "/usr/local/lib/python3.10/site-packages/telebot/__init__.py", line 611, in infinity_polling
    self.polling(none_stop=True, timeout=timeout, long_polling_timeout=long_polling_timeout,
  File "/usr/local/lib/python3.10/site-packages/telebot/__init__.py", line 658, in polling
    self.__threaded_polling(non_stop, interval, timeout, long_polling_timeout, allowed_updates)
  File "/usr/local/lib/python3.10/site-packages/telebot/__init__.py", line 720, in __threaded_polling
    raise e
  File "/usr/local/lib/python3.10/site-packages/telebot/__init__.py", line 680, in __threaded_polling
    self.worker_pool.raise_exceptions()
  File "/usr/local/lib/python3.10/site-packages/telebot/util.py", line 135, in raise_exceptions
    raise self.exception_info
  File "/usr/local/lib/python3.10/site-packages/telebot/util.py", line 87, in run
    task(*args, **kwargs)
  File "/home/RemBot/client/bot.py", line 105, in callback_query_handler
    handler(bot, call)
  File "/home/RemBot/client/handlers.py", line 176, in discounts_callback_query_handler
    text = Messages.DISCOUNTS.format(name=user.name)
KeyError: 'bonus'
"
2022-07-26 10:46:09,634 (__init__.py:615 MainThread) ERROR - TeleBot: "Infinity polling exception: 'bonus'"
2022-07-26 10:46:09,635 (__init__.py:617 MainThread) ERROR - TeleBot: "Exception traceback:
Traceback (most recent call last):
  File "/usr/local/lib/python3.10/site-packages/telebot/__init__.py", line 611, in infinity_polling
    self.polling(none_stop=True, timeout=timeout, long_polling_timeout=long_polling_timeout,
  File "/usr/local/lib/python3.10/site-packages/telebot/__init__.py", line 658, in polling
    self.__threaded_polling(non_stop, interval, timeout, long_polling_timeout, allowed_updates)
  File "/usr/local/lib/python3.10/site-packages/telebot/__init__.py", line 720, in __threaded_polling
    raise e
  File "/usr/local/lib/python3.10/site-packages/telebot/__init__.py", line 680, in __threaded_polling
    self.worker_pool.raise_exceptions()
  File "/usr/local/lib/python3.10/site-packages/telebot/util.py", line 135, in raise_exceptions
    raise self.exception_info
  File "/usr/local/lib/python3.10/site-packages/telebot/util.py", line 87, in run
    task(*args, **kwargs)
  File "/home/RemBot/client/bot.py", line 105, in callback_query_handler
    handler(bot, call)
  File "/home/RemBot/client/handlers.py", line 176, in discounts_callback_query_handler
    text = Messages.DISCOUNTS.format(name=user.name)
KeyError: 'bonus'
"
2022-07-26 10:46:46,274 (__init__.py:615 MainThread) ERROR - TeleBot: "Infinity polling exception: 'bonus'"
2022-07-26 10:46:46,274 (__init__.py:617 MainThread) ERROR - TeleBot: "Exception traceback:
Traceback (most recent call last):
  File "/usr/local/lib/python3.10/site-packages/telebot/__init__.py", line 611, in infinity_polling
    self.polling(none_stop=True, timeout=timeout, long_polling_timeout=long_polling_timeout,
  File "/usr/local/lib/python3.10/site-packages/telebot/__init__.py", line 658, in polling
    self.__threaded_polling(non_stop, interval, timeout, long_polling_timeout, allowed_updates)
  File "/usr/local/lib/python3.10/site-packages/telebot/__init__.py", line 720, in __threaded_polling
    raise e
  File "/usr/local/lib/python3.10/site-packages/telebot/__init__.py", line 680, in __threaded_polling
    self.worker_pool.raise_exceptions()
  File "/usr/local/lib/python3.10/site-packages/telebot/util.py", line 135, in raise_exceptions
    raise self.exception_info
  File "/usr/local/lib/python3.10/site-packages/telebot/util.py", line 87, in run
    task(*args, **kwargs)
  File "/home/RemBot/client/bot.py", line 105, in callback_query_handler
    handler(bot, call)
  File "/home/RemBot/client/handlers.py", line 176, in discounts_callback_query_handler
    text = Messages.DISCOUNTS.format(name=user.name)
KeyError: 'bonus'
"
2022-07-26 10:46:49,279 (__init__.py:615 MainThread) ERROR - TeleBot: "Infinity polling exception: 'bonus'"
2022-07-26 10:46:49,279 (__init__.py:617 MainThread) ERROR - TeleBot: "Exception traceback:
Traceback (most recent call last):
  File "/usr/local/lib/python3.10/site-packages/telebot/__init__.py", line 611, in infinity_polling
    self.polling(none_stop=True, timeout=timeout, long_polling_timeout=long_polling_timeout,
  File "/usr/local/lib/python3.10/site-packages/telebot/__init__.py", line 658, in polling
    self.__threaded_polling(non_stop, interval, timeout, long_polling_timeout, allowed_updates)
  File "/usr/local/lib/python3.10/site-packages/telebot/__init__.py", line 720, in __threaded_polling
    raise e
  File "/usr/local/lib/python3.10/site-packages/telebot/__init__.py", line 680, in __threaded_polling
    self.worker_pool.raise_exceptions()
  File "/usr/local/lib/python3.10/site-packages/telebot/util.py", line 135, in raise_exceptions
    raise self.exception_info
  File "/usr/local/lib/python3.10/site-packages/telebot/util.py", line 87, in run
    task(*args, **kwargs)
  File "/home/RemBot/client/bot.py", line 105, in callback_query_handler
    handler(bot, call)
  File "/home/RemBot/client/handlers.py", line 176, in discounts_callback_query_handler
    text = Messages.DISCOUNTS.format(name=user.name)
KeyError: 'bonus'
"
2022-07-26 10:46:52,284 (__init__.py:615 MainThread) ERROR - TeleBot: "Infinity polling exception: 'bonus'"
2022-07-26 10:46:52,285 (__init__.py:617 MainThread) ERROR - TeleBot: "Exception traceback:
Traceback (most recent call last):
  File "/usr/local/lib/python3.10/site-packages/telebot/__init__.py", line 611, in infinity_polling
    self.polling(none_stop=True, timeout=timeout, long_polling_timeout=long_polling_timeout,
  File "/usr/local/lib/python3.10/site-packages/telebot/__init__.py", line 658, in polling
    self.__threaded_polling(non_stop, interval, timeout, long_polling_timeout, allowed_updates)
  File "/usr/local/lib/python3.10/site-packages/telebot/__init__.py", line 720, in __threaded_polling
    raise e
  File "/usr/local/lib/python3.10/site-packages/telebot/__init__.py", line 680, in __threaded_polling
    self.worker_pool.raise_exceptions()
  File "/usr/local/lib/python3.10/site-packages/telebot/util.py", line 135, in raise_exceptions
    raise self.exception_info
  File "/usr/local/lib/python3.10/site-packages/telebot/util.py", line 87, in run
    task(*args, **kwargs)
  File "/home/RemBot/client/bot.py", line 105, in callback_query_handler
    handler(bot, call)
  File "/home/RemBot/client/handlers.py", line 176, in discounts_callback_query_handler
    text = Messages.DISCOUNTS.format(name=user.name)
KeyError: 'bonus'
"
2022-07-26 10:46:55,289 (__init__.py:615 MainThread) ERROR - TeleBot: "Infinity polling exception: 'bonus'"
2022-07-26 10:46:55,291 (__init__.py:617 MainThread) ERROR - TeleBot: "Exception traceback:
Traceback (most recent call last):
  File "/usr/local/lib/python3.10/site-packages/telebot/__init__.py", line 611, in infinity_polling
    self.polling(none_stop=True, timeout=timeout, long_polling_timeout=long_polling_timeout,
  File "/usr/local/lib/python3.10/site-packages/telebot/__init__.py", line 658, in polling
    self.__threaded_polling(non_stop, interval, timeout, long_polling_timeout, allowed_updates)
  File "/usr/local/lib/python3.10/site-packages/telebot/__init__.py", line 720, in __threaded_polling
    raise e
  File "/usr/local/lib/python3.10/site-packages/telebot/__init__.py", line 680, in __threaded_polling
    self.worker_pool.raise_exceptions()
  File "/usr/local/lib/python3.10/site-packages/telebot/util.py", line 135, in raise_exceptions
    raise self.exception_info
  File "/usr/local/lib/python3.10/site-packages/telebot/util.py", line 87, in run
    task(*args, **kwargs)
  File "/home/RemBot/client/bot.py", line 105, in callback_query_handler
    handler(bot, call)
  File "/home/RemBot/client/handlers.py", line 176, in discounts_callback_query_handler
    text = Messages.DISCOUNTS.format(name=user.name)
KeyError: 'bonus'
"
2022-07-26 10:46:58,443 (__init__.py:615 MainThread) ERROR - TeleBot: "Infinity polling exception: 'bonus'"
2022-07-26 10:46:58,443 (__init__.py:617 MainThread) ERROR - TeleBot: "Exception traceback:
Traceback (most recent call last):
  File "/usr/local/lib/python3.10/site-packages/telebot/__init__.py", line 611, in infinity_polling
    self.polling(none_stop=True, timeout=timeout, long_polling_timeout=long_polling_timeout,
  File "/usr/local/lib/python3.10/site-packages/telebot/__init__.py", line 658, in polling
    self.__threaded_polling(non_stop, interval, timeout, long_polling_timeout, allowed_updates)
  File "/usr/local/lib/python3.10/site-packages/telebot/__init__.py", line 720, in __threaded_polling
    raise e
  File "/usr/local/lib/python3.10/site-packages/telebot/__init__.py", line 680, in __threaded_polling
    self.worker_pool.raise_exceptions()
  File "/usr/local/lib/python3.10/site-packages/telebot/util.py", line 135, in raise_exceptions
    raise self.exception_info
  File "/usr/local/lib/python3.10/site-packages/telebot/util.py", line 87, in run
    task(*args, **kwargs)
  File "/home/RemBot/client/bot.py", line 105, in callback_query_handler
    handler(bot, call)
  File "/home/RemBot/client/handlers.py", line 176, in discounts_callback_query_handler
    text = Messages.DISCOUNTS.format(name=user.name)
KeyError: 'bonus'
"
2022-07-26 10:47:09,075 (__init__.py:615 MainThread) ERROR - TeleBot: "Infinity polling exception: 'bonus'"
2022-07-26 10:47:09,075 (__init__.py:617 MainThread) ERROR - TeleBot: "Exception traceback:
Traceback (most recent call last):
  File "/usr/local/lib/python3.10/site-packages/telebot/__init__.py", line 611, in infinity_polling
    self.polling(none_stop=True, timeout=timeout, long_polling_timeout=long_polling_timeout,
  File "/usr/local/lib/python3.10/site-packages/telebot/__init__.py", line 658, in polling
    self.__threaded_polling(non_stop, interval, timeout, long_polling_timeout, allowed_updates)
  File "/usr/local/lib/python3.10/site-packages/telebot/__init__.py", line 720, in __threaded_polling
    raise e
  File "/usr/local/lib/python3.10/site-packages/telebot/__init__.py", line 680, in __threaded_polling
    self.worker_pool.raise_exceptions()
  File "/usr/local/lib/python3.10/site-packages/telebot/util.py", line 135, in raise_exceptions
    raise self.exception_info
  File "/usr/local/lib/python3.10/site-packages/telebot/util.py", line 87, in run
    task(*args, **kwargs)
  File "/home/RemBot/client/bot.py", line 105, in callback_query_handler
    handler(bot, call)
  File "/home/RemBot/client/handlers.py", line 176, in discounts_callback_query_handler
    text = Messages.DISCOUNTS.format(name=user.name)
KeyError: 'bonus'
"
2022-07-26 11:21:26,295 (__init__.py:615 MainThread) ERROR - TeleBot: "Infinity polling exception: 'bonus'"
2022-07-26 11:21:26,296 (__init__.py:617 MainThread) ERROR - TeleBot: "Exception traceback:
Traceback (most recent call last):
  File "/usr/local/lib/python3.10/site-packages/telebot/__init__.py", line 611, in infinity_polling
    self.polling(none_stop=True, timeout=timeout, long_polling_timeout=long_polling_timeout,
  File "/usr/local/lib/python3.10/site-packages/telebot/__init__.py", line 658, in polling
    self.__threaded_polling(non_stop, interval, timeout, long_polling_timeout, allowed_updates)
  File "/usr/local/lib/python3.10/site-packages/telebot/__init__.py", line 720, in __threaded_polling
    raise e
  File "/usr/local/lib/python3.10/site-packages/telebot/__init__.py", line 680, in __threaded_polling
    self.worker_pool.raise_exceptions()
  File "/usr/local/lib/python3.10/site-packages/telebot/util.py", line 135, in raise_exceptions
    raise self.exception_info
  File "/usr/local/lib/python3.10/site-packages/telebot/util.py", line 87, in run
    task(*args, **kwargs)
  File "/home/RemBot/client/bot.py", line 105, in callback_query_handler
    handler(bot, call)
  File "/home/RemBot/client/handlers.py", line 176, in discounts_callback_query_handler
    text = Messages.DISCOUNTS.format(name=user.name)
KeyError: 'bonus'
"
2022-07-26 11:21:59,156 (__init__.py:615 MainThread) ERROR - TeleBot: "Infinity polling exception: 'bonus'"
2022-07-26 11:21:59,157 (__init__.py:617 MainThread) ERROR - TeleBot: "Exception traceback:
Traceback (most recent call last):
  File "/usr/local/lib/python3.10/site-packages/telebot/__init__.py", line 611, in infinity_polling
    self.polling(none_stop=True, timeout=timeout, long_polling_timeout=long_polling_timeout,
  File "/usr/local/lib/python3.10/site-packages/telebot/__init__.py", line 658, in polling
    self.__threaded_polling(non_stop, interval, timeout, long_polling_timeout, allowed_updates)
  File "/usr/local/lib/python3.10/site-packages/telebot/__init__.py", line 720, in __threaded_polling
    raise e
  File "/usr/local/lib/python3.10/site-packages/telebot/__init__.py", line 680, in __threaded_polling
    self.worker_pool.raise_exceptions()
  File "/usr/local/lib/python3.10/site-packages/telebot/util.py", line 135, in raise_exceptions
    raise self.exception_info
  File "/usr/local/lib/python3.10/site-packages/telebot/util.py", line 87, in run
    task(*args, **kwargs)
  File "/home/RemBot/client/bot.py", line 105, in callback_query_handler
    handler(bot, call)
  File "/home/RemBot/client/handlers.py", line 176, in discounts_callback_query_handler
    text = Messages.DISCOUNTS.format(name=user.name)
KeyError: 'bonus'
"
2022-07-26 11:22:33,728 (__init__.py:615 MainThread) ERROR - TeleBot: "Infinity polling exception: 'bonus'"
2022-07-26 11:22:33,728 (__init__.py:617 MainThread) ERROR - TeleBot: "Exception traceback:
Traceback (most recent call last):
  File "/usr/local/lib/python3.10/site-packages/telebot/__init__.py", line 611, in infinity_polling
    self.polling(none_stop=True, timeout=timeout, long_polling_timeout=long_polling_timeout,
  File "/usr/local/lib/python3.10/site-packages/telebot/__init__.py", line 658, in polling
    self.__threaded_polling(non_stop, interval, timeout, long_polling_timeout, allowed_updates)
  File "/usr/local/lib/python3.10/site-packages/telebot/__init__.py", line 720, in __threaded_polling
    raise e
  File "/usr/local/lib/python3.10/site-packages/telebot/__init__.py", line 680, in __threaded_polling
    self.worker_pool.raise_exceptions()
  File "/usr/local/lib/python3.10/site-packages/telebot/util.py", line 135, in raise_exceptions
    raise self.exception_info
  File "/usr/local/lib/python3.10/site-packages/telebot/util.py", line 87, in run
    task(*args, **kwargs)
  File "/home/RemBot/client/bot.py", line 105, in callback_query_handler
    handler(bot, call)
  File "/home/RemBot/client/handlers.py", line 176, in discounts_callback_query_handler
    text = Messages.DISCOUNTS.format(name=user.name)
KeyError: 'bonus'
"
2022-07-26 11:23:05,419 (__init__.py:615 MainThread) ERROR - TeleBot: "Infinity polling exception: 'bonus'"
2022-07-26 11:23:05,419 (__init__.py:617 MainThread) ERROR - TeleBot: "Exception traceback:
Traceback (most recent call last):
  File "/usr/local/lib/python3.10/site-packages/telebot/__init__.py", line 611, in infinity_polling
    self.polling(none_stop=True, timeout=timeout, long_polling_timeout=long_polling_timeout,
  File "/usr/local/lib/python3.10/site-packages/telebot/__init__.py", line 658, in polling
    self.__threaded_polling(non_stop, interval, timeout, long_polling_timeout, allowed_updates)
  File "/usr/local/lib/python3.10/site-packages/telebot/__init__.py", line 720, in __threaded_polling
    raise e
  File "/usr/local/lib/python3.10/site-packages/telebot/__init__.py", line 680, in __threaded_polling
    self.worker_pool.raise_exceptions()
  File "/usr/local/lib/python3.10/site-packages/telebot/util.py", line 135, in raise_exceptions
    raise self.exception_info
  File "/usr/local/lib/python3.10/site-packages/telebot/util.py", line 87, in run
    task(*args, **kwargs)
  File "/home/RemBot/client/bot.py", line 105, in callback_query_handler
    handler(bot, call)
  File "/home/RemBot/client/handlers.py", line 176, in discounts_callback_query_handler
    text = Messages.DISCOUNTS.format(name=user.name)
KeyError: 'bonus'
"
2022-07-26 11:37:24,219 (__init__.py:615 MainThread) ERROR - TeleBot: "Infinity polling exception: 'bonus'"
2022-07-26 11:37:24,219 (__init__.py:617 MainThread) ERROR - TeleBot: "Exception traceback:
Traceback (most recent call last):
  File "/usr/local/lib/python3.10/site-packages/telebot/__init__.py", line 611, in infinity_polling
    self.polling(none_stop=True, timeout=timeout, long_polling_timeout=long_polling_timeout,
  File "/usr/local/lib/python3.10/site-packages/telebot/__init__.py", line 658, in polling
    self.__threaded_polling(non_stop, interval, timeout, long_polling_timeout, allowed_updates)
  File "/usr/local/lib/python3.10/site-packages/telebot/__init__.py", line 720, in __threaded_polling
    raise e
  File "/usr/local/lib/python3.10/site-packages/telebot/__init__.py", line 680, in __threaded_polling
    self.worker_pool.raise_exceptions()
  File "/usr/local/lib/python3.10/site-packages/telebot/util.py", line 135, in raise_exceptions
    raise self.exception_info
  File "/usr/local/lib/python3.10/site-packages/telebot/util.py", line 87, in run
    task(*args, **kwargs)
  File "/home/RemBot/client/bot.py", line 105, in callback_query_handler
    handler(bot, call)
  File "/home/RemBot/client/handlers.py", line 176, in discounts_callback_query_handler
    text = Messages.DISCOUNTS.format(name=user.name)
KeyError: 'bonus'
"
2022-07-26 11:47:31,714 (__init__.py:615 MainThread) ERROR - TeleBot: "Infinity polling exception: 'bonus'"
2022-07-26 11:47:31,714 (__init__.py:617 MainThread) ERROR - TeleBot: "Exception traceback:
Traceback (most recent call last):
  File "/usr/local/lib/python3.10/site-packages/telebot/__init__.py", line 611, in infinity_polling
    self.polling(none_stop=True, timeout=timeout, long_polling_timeout=long_polling_timeout,
  File "/usr/local/lib/python3.10/site-packages/telebot/__init__.py", line 658, in polling
    self.__threaded_polling(non_stop, interval, timeout, long_polling_timeout, allowed_updates)
  File "/usr/local/lib/python3.10/site-packages/telebot/__init__.py", line 720, in __threaded_polling
    raise e
  File "/usr/local/lib/python3.10/site-packages/telebot/__init__.py", line 680, in __threaded_polling
    self.worker_pool.raise_exceptions()
  File "/usr/local/lib/python3.10/site-packages/telebot/util.py", line 135, in raise_exceptions
    raise self.exception_info
  File "/usr/local/lib/python3.10/site-packages/telebot/util.py", line 87, in run
    task(*args, **kwargs)
  File "/home/RemBot/client/bot.py", line 105, in callback_query_handler
    handler(bot, call)
  File "/home/RemBot/client/handlers.py", line 176, in discounts_callback_query_handler
    text = Messages.DISCOUNTS.format(name=user.name)
KeyError: 'bonus'
"
2022-07-26 11:47:46,207 (__init__.py:615 MainThread) ERROR - TeleBot: "Infinity polling exception: 'bonus'"
2022-07-26 11:47:46,207 (__init__.py:617 MainThread) ERROR - TeleBot: "Exception traceback:
Traceback (most recent call last):
  File "/usr/local/lib/python3.10/site-packages/telebot/__init__.py", line 611, in infinity_polling
    self.polling(none_stop=True, timeout=timeout, long_polling_timeout=long_polling_timeout,
  File "/usr/local/lib/python3.10/site-packages/telebot/__init__.py", line 658, in polling
    self.__threaded_polling(non_stop, interval, timeout, long_polling_timeout, allowed_updates)
  File "/usr/local/lib/python3.10/site-packages/telebot/__init__.py", line 720, in __threaded_polling
    raise e
  File "/usr/local/lib/python3.10/site-packages/telebot/__init__.py", line 680, in __threaded_polling
    self.worker_pool.raise_exceptions()
  File "/usr/local/lib/python3.10/site-packages/telebot/util.py", line 135, in raise_exceptions
    raise self.exception_info
  File "/usr/local/lib/python3.10/site-packages/telebot/util.py", line 87, in run
    task(*args, **kwargs)
  File "/home/RemBot/client/bot.py", line 105, in callback_query_handler
    handler(bot, call)
  File "/home/RemBot/client/handlers.py", line 176, in discounts_callback_query_handler
    text = Messages.DISCOUNTS.format(name=user.name)
KeyError: 'bonus'
"
